<?xml version="1.0" ?>
<sdf version="1.5">

    <model name="vehicle_no_motor">
      <model name="chassis_v2">
        <pose>0 0 0.0132 0 0 0</pose>
        <link name="link">
          <inertial>
            <mass>0.1</mass>
            <inertia>
              <ixx>0.0001</ixx>
              <ixy>0</ixy>
              <ixz>0</ixz>
              <iyy>0.0001</iyy>
              <iyz>0</iyz>
              <izz>0.0001</izz>
            </inertia>
          </inertial>
          <collision name="collision">
            <pose>0.0005 -0.00065 0 1.57079632679 0 0</pose>
            <geometry>
              <box>
                <size>0.051 0.0035 0.153</size>
              </box>
            </geometry>
          </collision>
          <visual name="visual">
            <pose>0 0 0.0 1.57079632679 0 0</pose>
            <geometry>
              <mesh>
                <uri>model://chassis_v2/meshes/chassis_v2.dae</uri>
                <scale>0.001 0.001 0.001</scale>
              </mesh>
            </geometry>
            <material>
              <script>
                <uri>file://media/materials/scripts/gazebo.material</uri>
                <name>Gazebo/Grey</name>
              </script>
            </material>
          </visual>
        </link>
      </model>

      <model name="axle_wheels">
        <pose>0 0.040 0.028 0 0 0</pose>
        <link name="link">
          <inertial>
            <mass>0.1</mass>
            <inertia>
              <ixx>0.0001</ixx>
              <ixy>0</ixy>
              <ixz>0</ixz>
              <iyy>0.0001</iyy>
              <iyz>0</iyz>
              <izz>0.0001</izz>
            </inertia>
          </inertial>
          <collision name="axle_collision">
            <pose>0 0 0.0 0 1.57079632679 0</pose>
            <geometry>
              <cylinder>
                <radius>0.0025</radius>
                <length>0.08</length>
              </cylinder>
            </geometry>
          </collision>
          <collision name="wheel_0_collision">
            <pose>-0.0405 0 0.0 0 1.57079632679 0</pose>
            <geometry>
              <cylinder>
                <radius>0.028</radius>
                <length>0.02</length>
              </cylinder>
            </geometry>
          </collision>
          <collision name="wheel_1_collision">
            <pose>0.0405 0 0.0 0 1.57079632679 0</pose>
            <geometry>
              <cylinder>
                <radius>0.028</radius>
                <length>0.02</length>
              </cylinder>
            </geometry>
          </collision>
          <visual name="visual">
            <pose>0 0 0.0 0 0 0</pose>
            <geometry>
              <mesh>
                <uri>model://axle_wheels/meshes/axle_wheels.dae</uri>
                <scale>0.001 0.001 0.001</scale>
              </mesh>
            </geometry>
            <material>
              <script>
                <uri>file://media/materials/scripts/gazebo.material</uri>
                <name>Gazebo/Grey</name>
              </script>
            </material>
          </visual>
        </link>
      </model>

      <model name="caster_wheel">
        <pose>0 -0.09 0.0058 0 0 0</pose>
        <link name="link">
          <!-- Physics -->
          <collision name="collision">
            <pose>0 0 0.0 0 0 0</pose>
            <geometry>
              <sphere>
                <radius>0.0057</radius>
              </sphere>
            </geometry>
          </collision>
          <inertial>
            <mass>0.1</mass>
            <pose>0 0 0 0 0 0</pose>
            <inertia>
              <ixx>0.0001</ixx>
              <ixy>0</ixy>
              <ixz>0</ixz>
              <iyy>0.0001</iyy>
              <iyz>0</iyz>
              <izz>0.0001</izz>
            </inertia>
          </inertial>
          <visual name="visual">
<!--            <pose>0.0 0 0.0026 0 0 1.57</pose>
            <geometry>
              <mesh>
                <uri>model://caster_wheel/meshes/caster_wheel.dae</uri>
                <scale>0.001 0.001 0.001</scale>
              </mesh>
            </geometry>-->
            <geometry>
              <sphere>
                <radius>0.0057</radius>
              </sphere>
            </geometry>
            <material>
              <script>
                <name>Gazebo/Grey</name>
              </script>
            </material>
          </visual>
        </link>
      </model>


      <model name="battery_9v">
        <pose>0 -0.057 0.025 0 0 -1.57</pose>
          <link name="link">
            <inertial>
              <mass>0.1</mass>
              <inertia>
                <ixx>0.0001</ixx>
                <ixy>0</ixy>
                <ixz>0</ixz>
                <iyy>0.0001</iyy>
                <iyz>0</iyz>
                <izz>0.0001</izz>
              </inertia>
            </inertial>
            <collision name="collision">
              <pose>0 0 0.0 0 0 0</pose>
              <geometry>
                <box>
                  <size>0.027 0.055 0.017</size>
                </box>
              </geometry>
            </collision>
            <visual name="visual">
              <pose>0 0 0.0 0 0 0</pose>
              <geometry>
                <mesh>
                  <uri>model://battery_9v/meshes/battery_9v.dae</uri>
                  <scale>0.001 0.001 0.001</scale>
                </mesh>
              </geometry>
              <material>
                <script>
                  <uri>file://media/materials/scripts/gazebo.material</uri>
                  <name>Gazebo/Grey</name>
                </script>
              </material>
            </visual>
          </link>
      </model>

      <joint name="chassis_v2_battery_9v_joint" type="revolute">
        <parent>chassis_v2::link</parent>
        <child>battery_9v::link</child>
        <axis>
          <xyz>0 0 1</xyz>
          <limit>
            <lower>0</lower>
            <upper>0</upper>
          </limit>
        </axis>
      </joint>

      <joint name="chassis_v2_axle_joint" type="revolute">
        <parent>chassis_v2::link</parent>
        <child>axle_wheels::link</child>
        <axis>
          <xyz>1 0 0</xyz>
          <limit>
            <lower>-1000000000000000</lower>
            <upper>1000000000000000</upper>
          </limit>
        </axis>
      </joint>
      <joint name="chassis_v2_caster_joint" type="ball">
        <parent>chassis_v2::link</parent>
        <child>caster_wheel::link</child>
      </joint>


    </model>


</sdf>
