<?xml version="1.0" ?>
<sdf version="1.5">

    <model name="vehicle_no_motor">
      <model name="chassis">
        <pose>0 0 0.0132 0 0 0</pose>
        <link name="link">
          <inertial>
            <mass>0.1</mass>
            <inertia>
              <ixx>0.0001</ixx>
              <ixy>0</ixy>
              <ixz>0</ixz>
              <iyy>0.0001</iyy>
              <iyz>0</iyz>
              <izz>0.0001</izz>
            </inertia>
          </inertial>
          <collision name="collision">
            <pose>0.0005 -0.00065 0 1.57079632679 0 0</pose>
            <geometry>
              <box>
                <size>0.051 0.0035 0.153</size>
              </box>
            </geometry>
          </collision>
          <visual name="visual">
            <pose>0 0 0.0 1.57079632679 0 0</pose>
            <geometry>
              <mesh>
                <uri>model://chassis/meshes/chassis.dae</uri>
                <scale>0.001 0.001 0.001</scale>
              </mesh>
            </geometry>
            <material>
              <script>
                <uri>file://media/materials/scripts/gazebo.material</uri>
                <name>Gazebo/Grey</name>
              </script>
            </material>
          </visual>
        </link>
      </model>

      <model name="axle_wheels">
        <pose>0 0.040 0.028 0 0 0</pose>
        <link name="link">
          <inertial>
            <mass>0.1</mass>
            <inertia>
              <ixx>0.0001</ixx>
              <ixy>0</ixy>
              <ixz>0</ixz>
              <iyy>0.0001</iyy>
              <iyz>0</iyz>
              <izz>0.0001</izz>
            </inertia>
          </inertial>
          <collision name="axle_collision">
            <pose>0 0 0.0 0 1.57079632679 0</pose>
            <geometry>
              <cylinder>
                <radius>0.0025</radius>
                <length>0.08</length>
              </cylinder>
            </geometry>
          </collision>
          <collision name="wheel_0_collision">
            <pose>-0.0405 0 0.0 0 1.57079632679 0</pose>
            <geometry>
              <cylinder>
                <radius>0.028</radius>
                <length>0.02</length>
              </cylinder>
            </geometry>
          </collision>
          <collision name="wheel_1_collision">
            <pose>0.0405 0 0.0 0 1.57079632679 0</pose>
            <geometry>
              <cylinder>
                <radius>0.028</radius>
                <length>0.02</length>
              </cylinder>
            </geometry>
          </collision>
          <visual name="visual">
            <pose>0 0 0.0 0 0 0</pose>
            <geometry>
              <mesh>
                <uri>model://axle_wheels/meshes/axle_wheels.dae</uri>
                <scale>0.001 0.001 0.001</scale>
              </mesh>
            </geometry>
            <material>
              <script>
                <uri>file://media/materials/scripts/gazebo.material</uri>
                <name>Gazebo/Grey</name>
              </script>
            </material>
          </visual>
        </link>
      </model>

      <model name="caster_wheel">
        <pose>0 -0.06 0.0058 0 0 0</pose>
        <link name="link">
          <inertial>
            <mass>0.1</mass>
            <inertia>
              <ixx>0.0001</ixx>
              <ixy>0</ixy>
              <ixz>0</ixz>
              <iyy>0.0001</iyy>
              <iyz>0</iyz>
              <izz>0.0001</izz>
            </inertia>
          </inertial>
          <collision name="collision">
            <pose>0 0 0.0 0 0 0</pose>
            <geometry>
              <sphere>
                <radius>0.0057</radius>
              </sphere>
            </geometry>
          </collision>

          <visual name="visual">
            <pose>0 0 0.0 0 0 0</pose>
            <geometry>
              <sphere>
                <radius>0.0057</radius>
              </sphere>
            </geometry>
            <material>
              <script>
                <uri>file://media/materials/scripts/gazebo.material</uri>
                <name>Gazebo/Grey</name>
              </script>
            </material>
          </visual>
        </link>
      </model>

      <model name="battery_pack">
        <pose>0 -0.057 0.025 0 0 0</pose>
        <link name="link">
          <inertial>
            <mass>0.1</mass>
            <inertia>
              <ixx>0.0001</ixx>
              <ixy>0</ixy>
              <ixz>0</ixz>
              <iyy>0.0001</iyy>
              <iyz>0</iyz>
              <izz>0.0001</izz>
            </inertia>
          </inertial>
          <collision name="collision">
            <pose>0 0 0.000 1.57079632679 0 0</pose>
            <geometry>
              <box>
                <size>0.065 0.018 0.07</size>
              </box>
            </geometry>
          </collision>
          <visual name="visual">
            <pose>0 0 0.003 1.57079632679 0 0</pose>
            <geometry>
              <mesh>
                <uri>model://battery_pack/meshes/battery_pack.dae</uri>
                <scale>0.001 0.001 0.001</scale>
              </mesh>
            </geometry>
            <material>
              <script>
                <uri>file://media/materials/scripts/gazebo.material</uri>
                <name>Gazebo/Grey</name>
              </script>
            </material>
          </visual>
        </link>
      </model>

      <model name="motor_box">
        <pose>0 0.013 0.0285 0 0 0</pose>
        <link name="link">
          <inertial>
            <mass>0.1</mass>
            <inertia>
              <ixx>0.0001</ixx>
              <ixy>0</ixy>
              <ixz>0</ixz>
              <iyy>0.0001</iyy>
              <iyz>0</iyz>
              <izz>0.0001</izz>
            </inertia>
          </inertial>
          <collision name="collision">
            <pose>0 0.0 0.013 1.57079632679 0 1.57079632679</pose>
            <geometry>
              <box>
                <size>0.06 0.001 0.04</size>
              </box>
            </geometry>
          </collision>
          <visual name="visual">
            <pose>0 0 0.0 1.57079632679 0 1.57079632679</pose>
            <geometry>
              <mesh>
                <uri>model://motor_box/meshes/motor_box.dae</uri>
                <scale>0.001 0.001 0.001</scale>
              </mesh>
            </geometry>
            <material>
              <script>
                <uri>file://media/materials/scripts/gazebo.material</uri>
                <name>Gazebo/Grey</name>
              </script>
            </material>
          </visual>
        </link>
      </model>

      <joint name="chassis_battery_pack_joint" type="revolute">
        <parent>vehicle_no_motor::chassis::link</parent>
        <child>vehicle_no_motor::battery_pack::link</child>
        <axis>
          <xyz>0 0 1</xyz>
          <limit>
            <lower>0</lower>
            <upper>0</upper>
          </limit>
        </axis>
      </joint>

      <joint name="chassis_motor_box_joint" type="revolute">
        <parent>vehicle_no_motor::chassis::link</parent>
        <child>vehicle_no_motor::motor_box::link</child>
        <axis>
          <xyz>0 0 1</xyz>
          <limit>
            <lower>0</lower>
            <upper>0</upper>
          </limit>
        </axis>
      </joint>

      <joint name="chassis_axle_joint" type="revolute">
        <parent>vehicle_no_motor::chassis::link</parent>
        <child>vehicle_no_motor::axle_wheels::link</child>
        <axis>
          <xyz>1 0 0</xyz>
          <limit>
            <lower>-1000000000000000</lower>
            <upper>1000000000000000</upper>
          </limit>
        </axis>
      </joint>

      <joint name="chassis_caster_joint" type="ball">
        <parent>vehicle_no_motor::chassis::link</parent>
        <child>vehicle_no_motor::caster_wheel::link</child>
      </joint>

    </model>


</sdf>
